[2025-06-20 22:08:10,569] INFO django.utils.autoreload run_with_reloader:667 - Watching for file changes with StatReloader
[2025-06-20 22:08:44,395] INFO django.server log_message:213 - "POST /api/auth/register/ HTTP/1.1" 201 182
[2025-06-20 22:08:45,656] INFO django.server log_message:213 - "POST /api/auth/webauthn/register/begin/ HTTP/1.1" 200 789
[2025-06-20 22:09:22,484] WARNING django.request log_response:253 - Bad Request: /api/auth/webauthn/register/complete/
[2025-06-20 22:09:22,494] WARNING django.server log_message:213 - "POST /api/auth/webauthn/register/complete/ HTTP/1.1" 400 79
[2025-06-20 22:10:37,801] INFO django.server log_message:213 - "OPTIONS /api/auth/webauthn/register/begin/ HTTP/1.1" 200 0
[2025-06-20 22:10:37,818] INFO django.server log_message:213 - "POST /api/auth/webauthn/register/begin/ HTTP/1.1" 200 789
[2025-06-20 22:11:54,785] WARNING django.request log_response:253 - Bad Request: /api/auth/webauthn/register/complete/
[2025-06-20 22:11:54,786] WARNING django.server log_message:213 - "POST /api/auth/webauthn/register/complete/ HTTP/1.1" 400 79
[2025-06-20 22:14:05,135] INFO django.utils.autoreload trigger_reload:265 - C:\Users\fazi\Desktop\machine task\secure-dashboard\backend\authentication\views.py changed, reloading.
[2025-06-20 22:14:06,713] INFO django.utils.autoreload run_with_reloader:667 - Watching for file changes with StatReloader
[2025-06-20 22:14:14,300] INFO django.utils.autoreload trigger_reload:265 - C:\Users\fazi\Desktop\machine task\secure-dashboard\backend\authentication\views.py changed, reloading.
[2025-06-20 22:14:15,324] INFO django.utils.autoreload run_with_reloader:667 - Watching for file changes with StatReloader
[2025-06-20 22:14:18,185] INFO django.utils.autoreload trigger_reload:265 - C:\Users\fazi\Desktop\machine task\secure-dashboard\backend\authentication\views.py changed, reloading.
[2025-06-20 22:14:19,261] INFO django.utils.autoreload run_with_reloader:667 - Watching for file changes with StatReloader
[2025-06-20 22:14:26,905] INFO django.utils.autoreload trigger_reload:265 - C:\Users\fazi\Desktop\machine task\secure-dashboard\backend\authentication\views.py changed, reloading.
[2025-06-20 22:14:28,037] INFO django.utils.autoreload run_with_reloader:667 - Watching for file changes with StatReloader
[2025-06-20 22:14:31,003] INFO django.utils.autoreload trigger_reload:265 - C:\Users\fazi\Desktop\machine task\secure-dashboard\backend\authentication\views.py changed, reloading.
[2025-06-20 22:14:32,214] INFO django.utils.autoreload run_with_reloader:667 - Watching for file changes with StatReloader
[2025-06-20 22:14:36,231] INFO django.utils.autoreload trigger_reload:265 - C:\Users\fazi\Desktop\machine task\secure-dashboard\backend\authentication\views.py changed, reloading.
[2025-06-20 22:14:37,540] INFO django.utils.autoreload run_with_reloader:667 - Watching for file changes with StatReloader
[2025-06-20 22:14:40,470] INFO django.utils.autoreload trigger_reload:265 - C:\Users\fazi\Desktop\machine task\secure-dashboard\backend\authentication\views.py changed, reloading.
[2025-06-20 22:14:41,414] INFO django.utils.autoreload run_with_reloader:667 - Watching for file changes with StatReloader
[2025-06-20 22:14:46,724] INFO django.utils.autoreload trigger_reload:265 - C:\Users\fazi\Desktop\machine task\secure-dashboard\backend\authentication\views.py changed, reloading.
[2025-06-20 22:14:48,004] INFO django.utils.autoreload run_with_reloader:667 - Watching for file changes with StatReloader
[2025-06-20 22:14:50,932] INFO django.utils.autoreload trigger_reload:265 - C:\Users\fazi\Desktop\machine task\secure-dashboard\backend\authentication\views.py changed, reloading.
[2025-06-20 22:14:52,259] INFO django.utils.autoreload run_with_reloader:667 - Watching for file changes with StatReloader
[2025-06-20 22:32:07,140] INFO django.server log_message:213 - "OPTIONS /api/auth/register/ HTTP/1.1" 200 0
[2025-06-20 22:32:07,389] WARNING django.request log_response:253 - Bad Request: /api/auth/register/
[2025-06-20 22:32:07,391] WARNING django.server log_message:213 - "POST /api/auth/register/ HTTP/1.1" 400 58
[2025-06-20 22:32:56,522] INFO django.server log_message:213 - "POST /api/auth/register/ HTTP/1.1" 201 183
[2025-06-20 22:33:05,185] INFO django.server log_message:213 - "POST /api/auth/webauthn/register/begin/ HTTP/1.1" 200 789
[2025-06-20 22:33:39,668] INFO django.server log_message:213 - "POST /api/auth/webauthn/register/begin/ HTTP/1.1" 200 789
[2025-06-20 22:34:00,337] WARNING django.request log_response:253 - Bad Request: /api/auth/webauthn/register/complete/
[2025-06-20 22:34:00,338] WARNING django.server log_message:213 - "POST /api/auth/webauthn/register/complete/ HTTP/1.1" 400 79
[2025-06-20 22:37:25,428] INFO django.utils.autoreload trigger_reload:265 - C:\Users\fazi\Desktop\machine task\secure-dashboard\backend\authentication\views.py changed, reloading.
[2025-06-20 22:37:27,583] INFO django.utils.autoreload run_with_reloader:667 - Watching for file changes with StatReloader
[2025-06-20 22:37:36,544] INFO django.utils.autoreload trigger_reload:265 - C:\Users\fazi\Desktop\machine task\secure-dashboard\backend\authentication\views.py changed, reloading.
[2025-06-20 22:37:37,698] INFO django.utils.autoreload run_with_reloader:667 - Watching for file changes with StatReloader
[2025-06-20 22:37:43,020] INFO django.utils.autoreload trigger_reload:265 - C:\Users\fazi\Desktop\machine task\secure-dashboard\backend\authentication\views.py changed, reloading.
[2025-06-20 22:37:43,996] INFO django.utils.autoreload run_with_reloader:667 - Watching for file changes with StatReloader
[2025-06-20 22:37:46,787] INFO django.utils.autoreload trigger_reload:265 - C:\Users\fazi\Desktop\machine task\secure-dashboard\backend\authentication\views.py changed, reloading.
[2025-06-20 22:37:47,857] INFO django.utils.autoreload run_with_reloader:667 - Watching for file changes with StatReloader
[2025-06-20 22:40:02,084] INFO django.utils.autoreload run_with_reloader:667 - Watching for file changes with StatReloader
[2025-06-20 22:40:09,997] INFO django.server log_message:213 - "POST /api/auth/webauthn/register/begin/ HTTP/1.1" 200 789
[2025-06-20 22:40:41,619] WARNING django.request log_response:253 - Bad Request: /api/auth/webauthn/register/complete/
[2025-06-20 22:40:41,620] WARNING django.server log_message:213 - "POST /api/auth/webauthn/register/complete/ HTTP/1.1" 400 79
[2025-06-20 22:42:36,196] INFO django.utils.autoreload trigger_reload:265 - C:\Users\fazi\Desktop\machine task\secure-dashboard\backend\authentication\views.py changed, reloading.
[2025-06-20 22:42:37,643] INFO django.utils.autoreload run_with_reloader:667 - Watching for file changes with StatReloader
[2025-06-20 22:42:48,128] INFO django.utils.autoreload trigger_reload:265 - C:\Users\fazi\Desktop\machine task\secure-dashboard\backend\authentication\views.py changed, reloading.
[2025-06-20 22:42:49,738] INFO django.utils.autoreload run_with_reloader:667 - Watching for file changes with StatReloader
[2025-06-20 22:43:31,963] INFO django.server log_message:213 - "POST /api/auth/webauthn/register/begin/ HTTP/1.1" 200 789
[2025-06-20 22:43:41,139] INFO django.server log_message:213 - "POST /api/auth/webauthn/register/begin/ HTTP/1.1" 200 789
[2025-06-20 22:45:37,877] INFO django.server log_message:213 - "POST /api/auth/webauthn/register/begin/ HTTP/1.1" 200 789
[2025-06-20 22:45:58,895] WARNING django.request log_response:253 - Bad Request: /api/auth/webauthn/register/complete/
[2025-06-20 22:45:58,896] WARNING django.server log_message:213 - "POST /api/auth/webauthn/register/complete/ HTTP/1.1" 400 96
[2025-06-20 22:46:56,640] INFO django.utils.autoreload trigger_reload:265 - C:\Users\fazi\Desktop\machine task\secure-dashboard\backend\authentication\views.py changed, reloading.
[2025-06-20 22:46:57,811] INFO django.utils.autoreload run_with_reloader:667 - Watching for file changes with StatReloader
[2025-06-20 22:47:19,052] INFO django.server log_message:213 - "POST /api/auth/webauthn/register/begin/ HTTP/1.1" 200 789
[2025-06-20 22:47:39,981] INFO django.server log_message:213 - "POST /api/auth/webauthn/register/complete/ HTTP/1.1" 200 260
[2025-06-20 22:49:13,305] INFO django.server log_message:213 - "OPTIONS /api/auth/webauthn/authenticate/begin/ HTTP/1.1" 200 0
[2025-06-20 22:49:13,438] ERROR django.request log_response:253 - Internal Server Error: /api/auth/webauthn/authenticate/begin/
Traceback (most recent call last):
  File "C:\Users\fazi\Desktop\machine task\secure-dashboard\backend\venv\Lib\site-packages\django\core\handlers\exception.py", line 55, in inner
    response = get_response(request)
               ^^^^^^^^^^^^^^^^^^^^^
  File "C:\Users\fazi\Desktop\machine task\secure-dashboard\backend\venv\Lib\site-packages\django\core\handlers\base.py", line 197, in _get_response
    response = wrapped_callback(request, *callback_args, **callback_kwargs)
               ^^^^^^^^^^^^^^^^^^^^^^^^^^^^^^^^^^^^^^^^^^^^^^^^^^^^^^^^^^^^
  File "C:\Users\fazi\Desktop\machine task\secure-dashboard\backend\venv\Lib\site-packages\django\views\decorators\csrf.py", line 65, in _view_wrapper
    return view_func(request, *args, **kwargs)
           ^^^^^^^^^^^^^^^^^^^^^^^^^^^^^^^^^^^
  File "C:\Users\fazi\Desktop\machine task\secure-dashboard\backend\venv\Lib\site-packages\django\views\generic\base.py", line 105, in view
    return self.dispatch(request, *args, **kwargs)
           ^^^^^^^^^^^^^^^^^^^^^^^^^^^^^^^^^^^^^^^
  File "C:\Users\fazi\Desktop\machine task\secure-dashboard\backend\venv\Lib\site-packages\rest_framework\views.py", line 515, in dispatch
    response = self.handle_exception(exc)
               ^^^^^^^^^^^^^^^^^^^^^^^^^^
  File "C:\Users\fazi\Desktop\machine task\secure-dashboard\backend\venv\Lib\site-packages\rest_framework\views.py", line 475, in handle_exception
    self.raise_uncaught_exception(exc)
  File "C:\Users\fazi\Desktop\machine task\secure-dashboard\backend\venv\Lib\site-packages\rest_framework\views.py", line 486, in raise_uncaught_exception
    raise exc
  File "C:\Users\fazi\Desktop\machine task\secure-dashboard\backend\venv\Lib\site-packages\rest_framework\views.py", line 512, in dispatch
    response = handler(request, *args, **kwargs)
               ^^^^^^^^^^^^^^^^^^^^^^^^^^^^^^^^^
  File "C:\Users\fazi\Desktop\machine task\secure-dashboard\backend\venv\Lib\site-packages\rest_framework\decorators.py", line 50, in handler
    return func(*args, **kwargs)
           ^^^^^^^^^^^^^^^^^^^^^
  File "C:\Users\fazi\Desktop\machine task\secure-dashboard\backend\authentication\views.py", line 486, in webauthn_authenticate_begin
    'allowCredentials': [
                        ^
  File "C:\Users\fazi\Desktop\machine task\secure-dashboard\backend\authentication\views.py", line 488, in <listcomp>
    'type': cred.type,
            ^^^^^^^^^
AttributeError: 'dict' object has no attribute 'type'
[2025-06-20 22:49:13,443] ERROR django.server log_message:213 - "POST /api/auth/webauthn/authenticate/begin/ HTTP/1.1" 500 115959
[2025-06-20 22:54:31,196] INFO django.utils.autoreload trigger_reload:265 - C:\Users\fazi\Desktop\machine task\secure-dashboard\backend\authentication\views.py changed, reloading.
[2025-06-20 22:54:32,639] INFO django.utils.autoreload run_with_reloader:667 - Watching for file changes with StatReloader
[2025-06-20 22:54:51,973] INFO django.utils.autoreload trigger_reload:265 - C:\Users\fazi\Desktop\machine task\secure-dashboard\backend\authentication\views.py changed, reloading.
[2025-06-20 22:54:53,202] INFO django.utils.autoreload run_with_reloader:667 - Watching for file changes with StatReloader
[2025-06-20 22:59:43,630] INFO django.utils.autoreload trigger_reload:265 - C:\Users\fazi\Desktop\machine task\secure-dashboard\backend\authentication\views.py changed, reloading.
[2025-06-20 22:59:44,833] INFO django.utils.autoreload run_with_reloader:667 - Watching for file changes with StatReloader
[2025-06-20 22:59:50,124] INFO django.utils.autoreload trigger_reload:265 - C:\Users\fazi\Desktop\machine task\secure-dashboard\backend\authentication\views.py changed, reloading.
[2025-06-20 22:59:51,415] INFO django.utils.autoreload run_with_reloader:667 - Watching for file changes with StatReloader
[2025-06-20 22:59:54,197] INFO django.utils.autoreload trigger_reload:265 - C:\Users\fazi\Desktop\machine task\secure-dashboard\backend\authentication\views.py changed, reloading.
[2025-06-20 22:59:55,139] INFO django.utils.autoreload run_with_reloader:667 - Watching for file changes with StatReloader
[2025-06-20 22:59:59,192] INFO django.utils.autoreload trigger_reload:265 - C:\Users\fazi\Desktop\machine task\secure-dashboard\backend\authentication\views.py changed, reloading.
[2025-06-20 23:00:00,169] INFO django.utils.autoreload run_with_reloader:667 - Watching for file changes with StatReloader
[2025-06-20 23:00:03,011] INFO django.utils.autoreload trigger_reload:265 - C:\Users\fazi\Desktop\machine task\secure-dashboard\backend\authentication\views.py changed, reloading.
[2025-06-20 23:00:04,316] INFO django.utils.autoreload run_with_reloader:667 - Watching for file changes with StatReloader
[2025-06-20 23:04:30,735] INFO django.utils.autoreload trigger_reload:265 - C:\Users\fazi\Desktop\machine task\secure-dashboard\backend\authentication\views.py changed, reloading.
[2025-06-20 23:04:32,247] INFO django.utils.autoreload run_with_reloader:667 - Watching for file changes with StatReloader
[2025-06-20 23:04:41,680] INFO django.utils.autoreload trigger_reload:265 - C:\Users\fazi\Desktop\machine task\secure-dashboard\backend\authentication\views.py changed, reloading.
[2025-06-20 23:04:42,767] INFO django.utils.autoreload run_with_reloader:667 - Watching for file changes with StatReloader
[2025-06-20 23:04:45,732] INFO django.utils.autoreload trigger_reload:265 - C:\Users\fazi\Desktop\machine task\secure-dashboard\backend\authentication\views.py changed, reloading.
[2025-06-20 23:04:46,680] INFO django.utils.autoreload run_with_reloader:667 - Watching for file changes with StatReloader
[2025-06-20 23:04:56,722] INFO django.utils.autoreload trigger_reload:265 - C:\Users\fazi\Desktop\machine task\secure-dashboard\backend\authentication\views.py changed, reloading.
[2025-06-20 23:04:57,703] INFO django.utils.autoreload run_with_reloader:667 - Watching for file changes with StatReloader
[2025-06-20 23:05:00,546] INFO django.utils.autoreload trigger_reload:265 - C:\Users\fazi\Desktop\machine task\secure-dashboard\backend\authentication\views.py changed, reloading.
[2025-06-20 23:05:01,646] INFO django.utils.autoreload run_with_reloader:667 - Watching for file changes with StatReloader
[2025-06-20 23:05:06,699] INFO django.utils.autoreload trigger_reload:265 - C:\Users\fazi\Desktop\machine task\secure-dashboard\backend\authentication\views.py changed, reloading.
[2025-06-20 23:05:07,688] INFO django.utils.autoreload run_with_reloader:667 - Watching for file changes with StatReloader
[2025-06-20 23:05:13,035] INFO django.utils.autoreload trigger_reload:265 - C:\Users\fazi\Desktop\machine task\secure-dashboard\backend\authentication\views.py changed, reloading.
[2025-06-20 23:05:13,987] INFO django.utils.autoreload run_with_reloader:667 - Watching for file changes with StatReloader
[2025-06-20 23:05:24,170] INFO django.utils.autoreload trigger_reload:265 - C:\Users\fazi\Desktop\machine task\secure-dashboard\backend\authentication\views.py changed, reloading.
[2025-06-20 23:05:25,154] INFO django.utils.autoreload run_with_reloader:667 - Watching for file changes with StatReloader
[2025-06-20 23:05:28,054] INFO django.utils.autoreload trigger_reload:265 - C:\Users\fazi\Desktop\machine task\secure-dashboard\backend\authentication\views.py changed, reloading.
[2025-06-20 23:05:29,241] INFO django.utils.autoreload run_with_reloader:667 - Watching for file changes with StatReloader
[2025-06-20 23:07:25,055] INFO django.utils.autoreload trigger_reload:265 - C:\Users\fazi\Desktop\machine task\secure-dashboard\backend\authentication\views.py changed, reloading.
[2025-06-20 23:07:26,209] INFO django.utils.autoreload run_with_reloader:667 - Watching for file changes with StatReloader
[2025-06-20 23:07:29,182] INFO django.utils.autoreload trigger_reload:265 - C:\Users\fazi\Desktop\machine task\secure-dashboard\backend\authentication\views.py changed, reloading.
[2025-06-20 23:07:30,214] INFO django.utils.autoreload run_with_reloader:667 - Watching for file changes with StatReloader
[2025-06-20 23:07:32,926] INFO django.utils.autoreload trigger_reload:265 - C:\Users\fazi\Desktop\machine task\secure-dashboard\backend\authentication\views.py changed, reloading.
[2025-06-20 23:07:33,919] INFO django.utils.autoreload run_with_reloader:667 - Watching for file changes with StatReloader
[2025-06-20 23:07:36,643] INFO django.utils.autoreload trigger_reload:265 - C:\Users\fazi\Desktop\machine task\secure-dashboard\backend\authentication\views.py changed, reloading.
[2025-06-20 23:07:37,621] INFO django.utils.autoreload run_with_reloader:667 - Watching for file changes with StatReloader
[2025-06-20 23:07:51,092] INFO django.utils.autoreload trigger_reload:265 - C:\Users\fazi\Desktop\machine task\secure-dashboard\backend\authentication\views.py changed, reloading.
[2025-06-20 23:07:52,198] INFO django.utils.autoreload run_with_reloader:667 - Watching for file changes with StatReloader
[2025-06-20 23:07:55,066] INFO django.utils.autoreload trigger_reload:265 - C:\Users\fazi\Desktop\machine task\secure-dashboard\backend\authentication\views.py changed, reloading.
[2025-06-20 23:07:56,166] INFO django.utils.autoreload run_with_reloader:667 - Watching for file changes with StatReloader
[2025-06-20 23:08:20,493] ERROR django.request log_response:253 - Internal Server Error: /api/auth/webauthn/authenticate/begin/
Traceback (most recent call last):
  File "C:\Users\fazi\Desktop\machine task\secure-dashboard\backend\venv\Lib\site-packages\django\core\handlers\exception.py", line 55, in inner
    response = get_response(request)
               ^^^^^^^^^^^^^^^^^^^^^
  File "C:\Users\fazi\Desktop\machine task\secure-dashboard\backend\venv\Lib\site-packages\django\core\handlers\base.py", line 197, in _get_response
    response = wrapped_callback(request, *callback_args, **callback_kwargs)
               ^^^^^^^^^^^^^^^^^^^^^^^^^^^^^^^^^^^^^^^^^^^^^^^^^^^^^^^^^^^^
  File "C:\Users\fazi\Desktop\machine task\secure-dashboard\backend\venv\Lib\site-packages\django\views\decorators\csrf.py", line 65, in _view_wrapper
    return view_func(request, *args, **kwargs)
           ^^^^^^^^^^^^^^^^^^^^^^^^^^^^^^^^^^^
  File "C:\Users\fazi\Desktop\machine task\secure-dashboard\backend\venv\Lib\site-packages\django\views\generic\base.py", line 105, in view
    return self.dispatch(request, *args, **kwargs)
           ^^^^^^^^^^^^^^^^^^^^^^^^^^^^^^^^^^^^^^^
  File "C:\Users\fazi\Desktop\machine task\secure-dashboard\backend\venv\Lib\site-packages\rest_framework\views.py", line 515, in dispatch
    response = self.handle_exception(exc)
               ^^^^^^^^^^^^^^^^^^^^^^^^^^
  File "C:\Users\fazi\Desktop\machine task\secure-dashboard\backend\venv\Lib\site-packages\rest_framework\views.py", line 475, in handle_exception
    self.raise_uncaught_exception(exc)
  File "C:\Users\fazi\Desktop\machine task\secure-dashboard\backend\venv\Lib\site-packages\rest_framework\views.py", line 486, in raise_uncaught_exception
    raise exc
  File "C:\Users\fazi\Desktop\machine task\secure-dashboard\backend\venv\Lib\site-packages\rest_framework\views.py", line 512, in dispatch
    response = handler(request, *args, **kwargs)
               ^^^^^^^^^^^^^^^^^^^^^^^^^^^^^^^^^
  File "C:\Users\fazi\Desktop\machine task\secure-dashboard\backend\venv\Lib\site-packages\rest_framework\decorators.py", line 50, in handler
    return func(*args, **kwargs)
           ^^^^^^^^^^^^^^^^^^^^^
  File "C:\Users\fazi\Desktop\machine task\secure-dashboard\backend\authentication\views.py", line 575, in webauthn_authenticate_begin
    'allowCredentials': [
                        ^
  File "C:\Users\fazi\Desktop\machine task\secure-dashboard\backend\authentication\views.py", line 577, in <listcomp>
    'type': cred.type,
            ^^^^^^^^^
AttributeError: 'dict' object has no attribute 'type'
[2025-06-20 23:08:20,498] ERROR django.server log_message:213 - "POST /api/auth/webauthn/authenticate/begin/ HTTP/1.1" 500 116024
[2025-06-20 23:08:44,233] INFO django.utils.autoreload run_with_reloader:667 - Watching for file changes with StatReloader
[2025-06-20 23:09:11,805] ERROR django.request log_response:253 - Internal Server Error: /api/auth/webauthn/authenticate/begin/
Traceback (most recent call last):
  File "C:\Users\fazi\Desktop\machine task\secure-dashboard\backend\venv\Lib\site-packages\django\core\handlers\exception.py", line 55, in inner
    response = get_response(request)
               ^^^^^^^^^^^^^^^^^^^^^
  File "C:\Users\fazi\Desktop\machine task\secure-dashboard\backend\venv\Lib\site-packages\django\core\handlers\base.py", line 197, in _get_response
    response = wrapped_callback(request, *callback_args, **callback_kwargs)
               ^^^^^^^^^^^^^^^^^^^^^^^^^^^^^^^^^^^^^^^^^^^^^^^^^^^^^^^^^^^^
  File "C:\Users\fazi\Desktop\machine task\secure-dashboard\backend\venv\Lib\site-packages\django\views\decorators\csrf.py", line 65, in _view_wrapper
    return view_func(request, *args, **kwargs)
           ^^^^^^^^^^^^^^^^^^^^^^^^^^^^^^^^^^^
  File "C:\Users\fazi\Desktop\machine task\secure-dashboard\backend\venv\Lib\site-packages\django\views\generic\base.py", line 105, in view
    return self.dispatch(request, *args, **kwargs)
           ^^^^^^^^^^^^^^^^^^^^^^^^^^^^^^^^^^^^^^^
  File "C:\Users\fazi\Desktop\machine task\secure-dashboard\backend\venv\Lib\site-packages\rest_framework\views.py", line 515, in dispatch
    response = self.handle_exception(exc)
               ^^^^^^^^^^^^^^^^^^^^^^^^^^
  File "C:\Users\fazi\Desktop\machine task\secure-dashboard\backend\venv\Lib\site-packages\rest_framework\views.py", line 475, in handle_exception
    self.raise_uncaught_exception(exc)
  File "C:\Users\fazi\Desktop\machine task\secure-dashboard\backend\venv\Lib\site-packages\rest_framework\views.py", line 486, in raise_uncaught_exception
    raise exc
  File "C:\Users\fazi\Desktop\machine task\secure-dashboard\backend\venv\Lib\site-packages\rest_framework\views.py", line 512, in dispatch
    response = handler(request, *args, **kwargs)
               ^^^^^^^^^^^^^^^^^^^^^^^^^^^^^^^^^
  File "C:\Users\fazi\Desktop\machine task\secure-dashboard\backend\venv\Lib\site-packages\rest_framework\decorators.py", line 50, in handler
    return func(*args, **kwargs)
           ^^^^^^^^^^^^^^^^^^^^^
  File "C:\Users\fazi\Desktop\machine task\secure-dashboard\backend\authentication\views.py", line 575, in webauthn_authenticate_begin
    'allowCredentials': [
                        ^
  File "C:\Users\fazi\Desktop\machine task\secure-dashboard\backend\authentication\views.py", line 577, in <listcomp>
    'type': cred.type,
            ^^^^^^^^^
AttributeError: 'dict' object has no attribute 'type'
[2025-06-20 23:09:11,813] ERROR django.server log_message:213 - "POST /api/auth/webauthn/authenticate/begin/ HTTP/1.1" 500 116024
[2025-06-20 23:12:43,515] INFO django.utils.autoreload trigger_reload:265 - C:\Users\fazi\Desktop\machine task\secure-dashboard\backend\authentication\views.py changed, reloading.
[2025-06-20 23:12:44,630] INFO django.utils.autoreload run_with_reloader:667 - Watching for file changes with StatReloader
[2025-06-20 23:12:53,253] INFO django.utils.autoreload trigger_reload:265 - C:\Users\fazi\Desktop\machine task\secure-dashboard\backend\authentication\views.py changed, reloading.
[2025-06-20 23:12:54,221] INFO django.utils.autoreload run_with_reloader:667 - Watching for file changes with StatReloader
[2025-06-20 23:14:26,782] ERROR django.request log_response:253 - Internal Server Error: /api/auth/webauthn/authenticate/begin/
Traceback (most recent call last):
  File "C:\Users\fazi\Desktop\machine task\secure-dashboard\backend\venv\Lib\site-packages\django\core\handlers\exception.py", line 55, in inner
    response = get_response(request)
               ^^^^^^^^^^^^^^^^^^^^^
  File "C:\Users\fazi\Desktop\machine task\secure-dashboard\backend\venv\Lib\site-packages\django\core\handlers\base.py", line 197, in _get_response
    response = wrapped_callback(request, *callback_args, **callback_kwargs)
               ^^^^^^^^^^^^^^^^^^^^^^^^^^^^^^^^^^^^^^^^^^^^^^^^^^^^^^^^^^^^
  File "C:\Users\fazi\Desktop\machine task\secure-dashboard\backend\venv\Lib\site-packages\django\views\decorators\csrf.py", line 65, in _view_wrapper
    return view_func(request, *args, **kwargs)
           ^^^^^^^^^^^^^^^^^^^^^^^^^^^^^^^^^^^
  File "C:\Users\fazi\Desktop\machine task\secure-dashboard\backend\venv\Lib\site-packages\django\views\generic\base.py", line 105, in view
    return self.dispatch(request, *args, **kwargs)
           ^^^^^^^^^^^^^^^^^^^^^^^^^^^^^^^^^^^^^^^
  File "C:\Users\fazi\Desktop\machine task\secure-dashboard\backend\venv\Lib\site-packages\rest_framework\views.py", line 515, in dispatch
    response = self.handle_exception(exc)
               ^^^^^^^^^^^^^^^^^^^^^^^^^^
  File "C:\Users\fazi\Desktop\machine task\secure-dashboard\backend\venv\Lib\site-packages\rest_framework\views.py", line 475, in handle_exception
    self.raise_uncaught_exception(exc)
  File "C:\Users\fazi\Desktop\machine task\secure-dashboard\backend\venv\Lib\site-packages\rest_framework\views.py", line 486, in raise_uncaught_exception
    raise exc
  File "C:\Users\fazi\Desktop\machine task\secure-dashboard\backend\venv\Lib\site-packages\rest_framework\views.py", line 512, in dispatch
    response = handler(request, *args, **kwargs)
               ^^^^^^^^^^^^^^^^^^^^^^^^^^^^^^^^^
  File "C:\Users\fazi\Desktop\machine task\secure-dashboard\backend\venv\Lib\site-packages\rest_framework\decorators.py", line 50, in handler
    return func(*args, **kwargs)
           ^^^^^^^^^^^^^^^^^^^^^
  File "C:\Users\fazi\Desktop\machine task\secure-dashboard\backend\authentication\views.py", line 575, in webauthn_authenticate_begin
    'allowCredentials': [
                        ^
  File "C:\Users\fazi\Desktop\machine task\secure-dashboard\backend\authentication\views.py", line 577, in <listcomp>
    'type': cred.type,
            ^^^^^^^^^
AttributeError: 'dict' object has no attribute 'type'
[2025-06-20 23:14:26,787] ERROR django.server log_message:213 - "POST /api/auth/webauthn/authenticate/begin/ HTTP/1.1" 500 115934
[2025-06-20 23:23:33,160] INFO django.utils.autoreload trigger_reload:265 - C:\Users\fazi\Desktop\machine task\secure-dashboard\backend\authentication\views.py changed, reloading.
[2025-06-20 23:23:34,967] INFO django.utils.autoreload run_with_reloader:667 - Watching for file changes with StatReloader
[2025-06-20 23:23:43,685] INFO django.utils.autoreload trigger_reload:265 - C:\Users\fazi\Desktop\machine task\secure-dashboard\backend\authentication\views.py changed, reloading.
[2025-06-20 23:23:44,834] INFO django.utils.autoreload run_with_reloader:667 - Watching for file changes with StatReloader
[2025-06-20 23:23:46,816] INFO django.utils.autoreload trigger_reload:265 - C:\Users\fazi\Desktop\machine task\secure-dashboard\backend\authentication\views.py changed, reloading.
[2025-06-20 23:23:47,710] INFO django.utils.autoreload run_with_reloader:667 - Watching for file changes with StatReloader
[2025-06-20 23:23:50,702] INFO django.utils.autoreload trigger_reload:265 - C:\Users\fazi\Desktop\machine task\secure-dashboard\backend\authentication\views.py changed, reloading.
[2025-06-20 23:23:51,864] INFO django.utils.autoreload run_with_reloader:667 - Watching for file changes with StatReloader
[2025-06-20 23:24:03,903] INFO django.utils.autoreload trigger_reload:265 - C:\Users\fazi\Desktop\machine task\secure-dashboard\backend\authentication\views.py changed, reloading.
[2025-06-20 23:24:04,828] INFO django.utils.autoreload run_with_reloader:667 - Watching for file changes with StatReloader
[2025-06-20 23:24:43,787] ERROR django.request log_response:253 - Internal Server Error: /api/auth/webauthn/authenticate/begin/
Traceback (most recent call last):
  File "C:\Users\fazi\Desktop\machine task\secure-dashboard\backend\venv\Lib\site-packages\django\core\handlers\exception.py", line 55, in inner
    response = get_response(request)
               ^^^^^^^^^^^^^^^^^^^^^
  File "C:\Users\fazi\Desktop\machine task\secure-dashboard\backend\venv\Lib\site-packages\django\core\handlers\base.py", line 197, in _get_response
    response = wrapped_callback(request, *callback_args, **callback_kwargs)
               ^^^^^^^^^^^^^^^^^^^^^^^^^^^^^^^^^^^^^^^^^^^^^^^^^^^^^^^^^^^^
  File "C:\Users\fazi\Desktop\machine task\secure-dashboard\backend\venv\Lib\site-packages\django\views\decorators\csrf.py", line 65, in _view_wrapper
    return view_func(request, *args, **kwargs)
           ^^^^^^^^^^^^^^^^^^^^^^^^^^^^^^^^^^^
  File "C:\Users\fazi\Desktop\machine task\secure-dashboard\backend\venv\Lib\site-packages\django\views\generic\base.py", line 105, in view
    return self.dispatch(request, *args, **kwargs)
           ^^^^^^^^^^^^^^^^^^^^^^^^^^^^^^^^^^^^^^^
  File "C:\Users\fazi\Desktop\machine task\secure-dashboard\backend\venv\Lib\site-packages\rest_framework\views.py", line 515, in dispatch
    response = self.handle_exception(exc)
               ^^^^^^^^^^^^^^^^^^^^^^^^^^
  File "C:\Users\fazi\Desktop\machine task\secure-dashboard\backend\venv\Lib\site-packages\rest_framework\views.py", line 475, in handle_exception
    self.raise_uncaught_exception(exc)
  File "C:\Users\fazi\Desktop\machine task\secure-dashboard\backend\venv\Lib\site-packages\rest_framework\views.py", line 486, in raise_uncaught_exception
    raise exc
  File "C:\Users\fazi\Desktop\machine task\secure-dashboard\backend\venv\Lib\site-packages\rest_framework\views.py", line 512, in dispatch
    response = handler(request, *args, **kwargs)
               ^^^^^^^^^^^^^^^^^^^^^^^^^^^^^^^^^
  File "C:\Users\fazi\Desktop\machine task\secure-dashboard\backend\venv\Lib\site-packages\rest_framework\decorators.py", line 50, in handler
    return func(*args, **kwargs)
           ^^^^^^^^^^^^^^^^^^^^^
  File "C:\Users\fazi\Desktop\machine task\secure-dashboard\backend\authentication\views.py", line 574, in webauthn_authenticate_begin
    logger.info(f"Allow credential: {cred.id}")
                                     ^^^^^^^
AttributeError: 'dict' object has no attribute 'id'
[2025-06-20 23:24:43,797] ERROR django.server log_message:213 - "POST /api/auth/webauthn/authenticate/begin/ HTTP/1.1" 500 112312
[2025-06-20 23:25:57,796] INFO django.utils.autoreload trigger_reload:265 - C:\Users\fazi\Desktop\machine task\secure-dashboard\backend\authentication\views.py changed, reloading.
[2025-06-20 23:25:59,030] INFO django.utils.autoreload run_with_reloader:667 - Watching for file changes with StatReloader
[2025-06-20 23:26:00,916] ERROR django.request log_response:253 - Internal Server Error: /api/auth/webauthn/authenticate/begin/
Traceback (most recent call last):
  File "C:\Users\fazi\Desktop\machine task\secure-dashboard\backend\venv\Lib\site-packages\django\core\handlers\exception.py", line 55, in inner
    response = get_response(request)
               ^^^^^^^^^^^^^^^^^^^^^
  File "C:\Users\fazi\Desktop\machine task\secure-dashboard\backend\venv\Lib\site-packages\django\core\handlers\base.py", line 197, in _get_response
    response = wrapped_callback(request, *callback_args, **callback_kwargs)
               ^^^^^^^^^^^^^^^^^^^^^^^^^^^^^^^^^^^^^^^^^^^^^^^^^^^^^^^^^^^^
  File "C:\Users\fazi\Desktop\machine task\secure-dashboard\backend\venv\Lib\site-packages\django\views\decorators\csrf.py", line 65, in _view_wrapper
    return view_func(request, *args, **kwargs)
           ^^^^^^^^^^^^^^^^^^^^^^^^^^^^^^^^^^^
  File "C:\Users\fazi\Desktop\machine task\secure-dashboard\backend\venv\Lib\site-packages\django\views\generic\base.py", line 105, in view
    return self.dispatch(request, *args, **kwargs)
           ^^^^^^^^^^^^^^^^^^^^^^^^^^^^^^^^^^^^^^^
  File "C:\Users\fazi\Desktop\machine task\secure-dashboard\backend\venv\Lib\site-packages\rest_framework\views.py", line 515, in dispatch
    response = self.handle_exception(exc)
               ^^^^^^^^^^^^^^^^^^^^^^^^^^
  File "C:\Users\fazi\Desktop\machine task\secure-dashboard\backend\venv\Lib\site-packages\rest_framework\views.py", line 475, in handle_exception
    self.raise_uncaught_exception(exc)
  File "C:\Users\fazi\Desktop\machine task\secure-dashboard\backend\venv\Lib\site-packages\rest_framework\views.py", line 486, in raise_uncaught_exception
    raise exc
  File "C:\Users\fazi\Desktop\machine task\secure-dashboard\backend\venv\Lib\site-packages\rest_framework\views.py", line 512, in dispatch
    response = handler(request, *args, **kwargs)
               ^^^^^^^^^^^^^^^^^^^^^^^^^^^^^^^^^
  File "C:\Users\fazi\Desktop\machine task\secure-dashboard\backend\venv\Lib\site-packages\rest_framework\decorators.py", line 50, in handler
    return func(*args, **kwargs)
           ^^^^^^^^^^^^^^^^^^^^^
  File "C:\Users\fazi\Desktop\machine task\secure-dashboard\backend\authentication\views.py", line 574, in webauthn_authenticate_begin
    logger.info(f"Allow credential: {cred.id}")
                                     ^^^^^^^
AttributeError: 'dict' object has no attribute 'id'
[2025-06-20 23:26:00,929] ERROR django.server log_message:213 - "POST /api/auth/webauthn/authenticate/begin/ HTTP/1.1" 500 112324
[2025-06-20 23:27:49,206] INFO django.utils.autoreload trigger_reload:265 - C:\Users\fazi\Desktop\machine task\secure-dashboard\backend\authentication\views.py changed, reloading.
[2025-06-20 23:27:50,853] INFO django.utils.autoreload run_with_reloader:667 - Watching for file changes with StatReloader
[2025-06-20 23:28:07,576] INFO django.server log_message:213 - "POST /api/auth/webauthn/authenticate/begin/ HTTP/1.1" 200 397
[2025-06-20 23:29:26,642] INFO django.server log_message:213 - "OPTIONS /api/auth/webauthn/authenticate/complete/ HTTP/1.1" 200 0
[2025-06-20 23:29:26,664] WARNING django.request log_response:253 - Bad Request: /api/auth/webauthn/authenticate/complete/
[2025-06-20 23:29:26,665] WARNING django.server log_message:213 - "POST /api/auth/webauthn/authenticate/complete/ HTTP/1.1" 400 114
[2025-06-20 23:30:01,291] INFO django.utils.autoreload trigger_reload:265 - C:\Users\fazi\Desktop\machine task\secure-dashboard\backend\authentication\views.py changed, reloading.
[2025-06-20 23:30:02,635] INFO django.utils.autoreload run_with_reloader:667 - Watching for file changes with StatReloader
[2025-06-20 23:33:21,610] INFO django.utils.autoreload trigger_reload:265 - C:\Users\fazi\Desktop\machine task\secure-dashboard\backend\authentication\views.py changed, reloading.
[2025-06-20 23:33:22,883] INFO django.utils.autoreload run_with_reloader:667 - Watching for file changes with StatReloader
[2025-06-20 23:33:28,194] INFO django.utils.autoreload trigger_reload:265 - C:\Users\fazi\Desktop\machine task\secure-dashboard\backend\authentication\views.py changed, reloading.
[2025-06-20 23:33:29,547] INFO django.utils.autoreload run_with_reloader:667 - Watching for file changes with StatReloader
[2025-06-20 23:33:32,813] INFO django.utils.autoreload trigger_reload:265 - C:\Users\fazi\Desktop\machine task\secure-dashboard\backend\authentication\views.py changed, reloading.
[2025-06-20 23:33:33,772] INFO django.utils.autoreload run_with_reloader:667 - Watching for file changes with StatReloader
[2025-06-20 23:33:36,776] INFO django.utils.autoreload trigger_reload:265 - C:\Users\fazi\Desktop\machine task\secure-dashboard\backend\authentication\views.py changed, reloading.
[2025-06-20 23:33:38,032] INFO django.utils.autoreload run_with_reloader:667 - Watching for file changes with StatReloader
[2025-06-20 23:33:40,878] INFO django.utils.autoreload trigger_reload:265 - C:\Users\fazi\Desktop\machine task\secure-dashboard\backend\authentication\views.py changed, reloading.
[2025-06-20 23:33:41,988] INFO django.utils.autoreload run_with_reloader:667 - Watching for file changes with StatReloader
[2025-06-20 23:34:33,150] INFO django.utils.autoreload trigger_reload:265 - C:\Users\fazi\Desktop\machine task\secure-dashboard\backend\authentication\views.py changed, reloading.
[2025-06-20 23:34:34,211] INFO django.utils.autoreload run_with_reloader:667 - Watching for file changes with StatReloader
[2025-06-20 23:34:35,370] INFO django.server log_message:213 - "POST /api/auth/webauthn/authenticate/begin/ HTTP/1.1" 200 397
[2025-06-20 23:34:54,733] INFO django.server log_message:213 - "POST /api/auth/webauthn/authenticate/begin/ HTTP/1.1" 200 397
[2025-06-20 23:35:26,573] INFO django.server log_message:213 - "POST /api/auth/webauthn/authenticate/begin/ HTTP/1.1" 200 397
[2025-06-20 23:36:11,857] INFO django.server log_message:213 - "POST /api/auth/webauthn/authenticate/complete/ HTTP/1.1" 200 676
[2025-06-20 23:38:02,121] INFO django.server log_message:213 - "OPTIONS /api/auth/profile/ HTTP/1.1" 200 0
[2025-06-20 23:38:02,122] INFO django.server log_message:213 - "OPTIONS /api/auth/profile/ HTTP/1.1" 200 0
[2025-06-20 23:38:02,132] INFO django.server log_message:213 - "GET /api/auth/profile/ HTTP/1.1" 200 133
[2025-06-20 23:38:02,139] INFO django.server log_message:213 - "GET /api/auth/profile/ HTTP/1.1" 200 133
[2025-06-20 23:44:22,550] WARNING django.request log_response:253 - Unauthorized: /api/auth/profile/
[2025-06-20 23:44:22,562] WARNING django.server log_message:213 - "GET /api/auth/profile/ HTTP/1.1" 401 58
[2025-06-20 23:48:49,898] INFO django.server log_message:213 - "GET /api/auth/profile/ HTTP/1.1" 200 133
[2025-06-20 23:49:12,997] INFO django.server log_message:213 - "POST /api/auth/webauthn/authenticate/begin/ HTTP/1.1" 200 397
[2025-06-20 23:50:49,061] INFO django.server log_message:213 - "POST /api/auth/webauthn/authenticate/complete/ HTTP/1.1" 200 676
[2025-06-20 23:50:49,116] INFO django.server log_message:213 - "GET /api/auth/profile/ HTTP/1.1" 200 133
[2025-06-20 23:50:49,126] INFO django.server log_message:213 - "GET /api/auth/profile/ HTTP/1.1" 200 133
[2025-06-21 00:27:34,405] INFO django.server log_message:213 - "GET /api/auth/profile/ HTTP/1.1" 200 133
[2025-06-21 00:27:34,418] INFO django.server log_message:213 - "GET /api/auth/profile/ HTTP/1.1" 200 133
[2025-06-21 00:27:34,461] INFO django.server log_message:213 - "GET /api/auth/profile/ HTTP/1.1" 200 133
[2025-06-21 00:27:34,472] INFO django.server log_message:213 - "GET /api/auth/profile/ HTTP/1.1" 200 133
[2025-06-21 00:29:04,921] INFO django.server log_message:213 - "POST /api/auth/register/ HTTP/1.1" 201 185
[2025-06-21 00:29:10,141] INFO django.server log_message:213 - "OPTIONS /api/auth/webauthn/register/begin/ HTTP/1.1" 200 0
[2025-06-21 00:29:10,164] INFO django.server log_message:213 - "POST /api/auth/webauthn/register/begin/ HTTP/1.1" 200 790
[2025-06-21 00:29:42,555] INFO django.server log_message:213 - "OPTIONS /api/auth/webauthn/register/complete/ HTTP/1.1" 200 0
[2025-06-21 00:29:42,905] INFO django.server log_message:213 - "POST /api/auth/webauthn/register/complete/ HTTP/1.1" 200 261
[2025-06-21 00:30:16,996] INFO django.server log_message:213 - "POST /api/auth/webauthn/authenticate/begin/ HTTP/1.1" 200 327
[2025-06-21 00:30:35,030] INFO django.server log_message:213 - "POST /api/auth/webauthn/authenticate/complete/ HTTP/1.1" 200 678
[2025-06-21 00:30:35,074] INFO django.server log_message:213 - "GET /api/auth/profile/ HTTP/1.1" 200 135
[2025-06-21 00:30:35,087] INFO django.server log_message:213 - "GET /api/auth/profile/ HTTP/1.1" 200 135
[2025-06-21 00:31:13,886] INFO django.server log_message:213 - "POST /api/auth/register/ HTTP/1.1" 201 185
[2025-06-21 00:31:15,225] INFO django.server log_message:213 - "POST /api/auth/webauthn/register/begin/ HTTP/1.1" 200 790
[2025-06-21 00:36:33,733] INFO django.server log_message:213 - "OPTIONS /api/auth/register/ HTTP/1.1" 200 0
[2025-06-21 00:36:34,239] INFO django.server log_message:213 - "POST /api/auth/register/ HTTP/1.1" 201 181
[2025-06-21 00:36:36,088] INFO django.server log_message:213 - "POST /api/auth/webauthn/register/begin/ HTTP/1.1" 200 784
[2025-06-21 00:37:51,078] INFO django.server log_message:213 - "POST /api/auth/webauthn/register/complete/ HTTP/1.1" 200 261
[2025-06-21 00:37:59,442] INFO django.server log_message:213 - "POST /api/auth/webauthn/authenticate/begin/ HTTP/1.1" 200 327
[2025-06-21 00:38:20,539] INFO django.server log_message:213 - "POST /api/auth/webauthn/authenticate/complete/ HTTP/1.1" 200 674
[2025-06-21 00:38:20,597] INFO django.server log_message:213 - "GET /api/auth/profile/ HTTP/1.1" 200 131
[2025-06-21 00:38:20,613] INFO django.server log_message:213 - "GET /api/auth/profile/ HTTP/1.1" 200 131
[2025-06-21 00:43:27,253] WARNING django.request log_response:253 - Not Found: /api/fetch/
[2025-06-21 00:43:27,256] WARNING django.server log_message:213 - "GET /api/fetch/ HTTP/1.1" 404 6095
[2025-06-21 00:43:29,982] WARNING django.request log_response:253 - Not Found: /api/update-status/1/
[2025-06-21 00:43:29,984] WARNING django.server log_message:213 - "GET /api/update-status/1/ HTTP/1.1" 404 6125
[2025-06-21 17:08:34,003] INFO django.utils.autoreload run_with_reloader:667 - Watching for file changes with StatReloader
[2025-06-21 18:00:54,439] INFO django.utils.autoreload trigger_reload:265 - C:\Users\fazi\Desktop\machine task\secure-dashboard\backend\dialer\views.py changed, reloading.
[2025-06-21 18:00:56,258] INFO django.utils.autoreload run_with_reloader:667 - Watching for file changes with StatReloader
[2025-06-21 18:01:20,124] INFO django.utils.autoreload trigger_reload:265 - C:\Users\fazi\Desktop\machine task\secure-dashboard\backend\secure_dashboard\settings.py changed, reloading.
[2025-06-21 18:01:21,154] INFO django.utils.autoreload run_with_reloader:667 - Watching for file changes with StatReloader
[2025-06-21 18:18:06,181] INFO django.utils.autoreload run_with_reloader:667 - Watching for file changes with StatReloader
[2025-06-21 18:18:52,730] INFO django.server log_message:213 - "OPTIONS /api/auth/webauthn/authenticate/begin/ HTTP/1.1" 200 0
[2025-06-21 18:18:52,751] INFO django.server log_message:213 - "POST /api/auth/webauthn/authenticate/begin/ HTTP/1.1" 200 327
[2025-06-21 18:19:26,612] INFO django.server log_message:213 - "OPTIONS /api/auth/webauthn/authenticate/complete/ HTTP/1.1" 200 0
[2025-06-21 18:19:26,753] INFO django.server log_message:213 - "POST /api/auth/webauthn/authenticate/complete/ HTTP/1.1" 200 678
[2025-06-21 18:19:26,803] INFO django.server log_message:213 - "OPTIONS /api/auth/profile/ HTTP/1.1" 200 0
[2025-06-21 18:19:26,805] INFO django.server log_message:213 - "OPTIONS /api/auth/profile/ HTTP/1.1" 200 0
[2025-06-21 18:19:26,818] INFO django.server log_message:213 - "GET /api/auth/profile/ HTTP/1.1" 200 135
[2025-06-21 18:19:26,826] INFO django.server log_message:213 - "GET /api/auth/profile/ HTTP/1.1" 200 135
[2025-06-21 18:19:33,024] INFO django.server log_message:213 - "OPTIONS /api/dialer/history/ HTTP/1.1" 200 0
[2025-06-21 18:19:33,024] INFO django.server log_message:213 - "OPTIONS /api/dialer/history/ HTTP/1.1" 200 0
[2025-06-21 18:19:33,069] WARNING django.request log_response:253 - Not Found: /api/dialer/history/
[2025-06-21 18:19:33,069] WARNING django.server log_message:213 - "GET /api/dialer/history/ HTTP/1.1" 404 7665
[2025-06-21 18:19:33,073] WARNING django.request log_response:253 - Not Found: /api/dialer/history/
[2025-06-21 18:19:33,074] WARNING django.server log_message:213 - "GET /api/dialer/history/ HTTP/1.1" 404 7665
[2025-06-21 18:19:46,072] INFO django.server log_message:213 - "GET /api/auth/profile/ HTTP/1.1" 200 135
[2025-06-21 18:19:46,080] INFO django.server log_message:213 - "GET /api/auth/profile/ HTTP/1.1" 200 135
[2025-06-21 18:20:36,095] WARNING django.request log_response:253 - Not Found: /api/dialer/history/
[2025-06-21 18:20:36,095] WARNING django.server log_message:213 - "GET /api/dialer/history/ HTTP/1.1" 404 7665
[2025-06-21 18:20:36,100] WARNING django.request log_response:253 - Not Found: /api/dialer/history/
[2025-06-21 18:20:36,101] WARNING django.server log_message:213 - "GET /api/dialer/history/ HTTP/1.1" 404 7665
[2025-06-21 18:20:44,862] INFO django.server log_message:213 - "OPTIONS /api/dialer/call/ HTTP/1.1" 200 0
[2025-06-21 18:20:44,873] WARNING django.request log_response:253 - Not Found: /api/dialer/call/
[2025-06-21 18:20:44,873] WARNING django.server log_message:213 - "POST /api/dialer/call/ HTTP/1.1" 404 7657
[2025-06-21 18:21:09,996] WARNING django.request log_response:253 - Not Found: /api/dialer/call/
[2025-06-21 18:21:09,997] WARNING django.server log_message:213 - "POST /api/dialer/call/ HTTP/1.1" 404 7657
[2025-06-21 18:21:16,470] WARNING django.request log_response:253 - Not Found: /api/dialer/call/
[2025-06-21 18:21:16,470] WARNING django.server log_message:213 - "GET /api/dialer/call/ HTTP/1.1" 404 7656
[2025-06-21 18:21:16,735] WARNING django.request log_response:253 - Not Found: /favicon.ico
[2025-06-21 18:21:16,737] WARNING django.server log_message:213 - "GET /favicon.ico HTTP/1.1" 404 2671
[2025-06-21 18:21:59,673] WARNING django.request log_response:253 - Not Found: /api/dialer/call/
[2025-06-21 18:21:59,674] WARNING django.server log_message:213 - "POST /api/dialer/call/ HTTP/1.1" 404 7657
[2025-06-21 18:22:20,050] INFO django.utils.autoreload trigger_reload:265 - C:\Users\fazi\Desktop\machine task\secure-dashboard\backend\secure_dashboard\settings.py changed, reloading.
[2025-06-21 18:22:21,352] INFO django.utils.autoreload run_with_reloader:667 - Watching for file changes with StatReloader
[2025-06-21 18:23:11,890] WARNING django.request log_response:253 - Not Found: /api/dialer/call/
[2025-06-21 18:23:11,891] WARNING django.server log_message:213 - "POST /api/dialer/call/ HTTP/1.1" 404 7657
[2025-06-21 18:25:07,909] INFO django.server log_message:213 - "OPTIONS /api/dialer/call/initiate/ HTTP/1.1" 200 0
[2025-06-21 18:25:08,781] ERROR django.request log_response:253 - Internal Server Error: /api/dialer/call/initiate/
[2025-06-21 18:25:08,783] ERROR django.server log_message:213 - "POST /api/dialer/call/initiate/ HTTP/1.1" 500 590
[2025-06-21 18:28:34,100] INFO django.server log_message:213 - "GET /api/auth/profile/ HTTP/1.1" 200 135
[2025-06-21 18:28:34,116] INFO django.server log_message:213 - "GET /api/auth/profile/ HTTP/1.1" 200 135
[2025-06-21 18:28:34,144] WARNING django.request log_response:253 - Not Found: /api/dialer/history/
[2025-06-21 18:28:34,145] WARNING django.server log_message:213 - "GET /api/dialer/history/ HTTP/1.1" 404 7665
[2025-06-21 18:28:34,155] WARNING django.request log_response:253 - Not Found: /api/dialer/history/
[2025-06-21 18:28:34,156] WARNING django.server log_message:213 - "GET /api/dialer/history/ HTTP/1.1" 404 7665
[2025-06-21 18:29:40,886] ERROR django.request log_response:253 - Internal Server Error: /api/dialer/call/initiate/
[2025-06-21 18:29:40,886] ERROR django.server log_message:213 - "POST /api/dialer/call/initiate/ HTTP/1.1" 500 590
[2025-06-21 18:29:54,000] ERROR django.request log_response:253 - Internal Server Error: /api/dialer/call/initiate/
[2025-06-21 18:29:54,001] ERROR django.server log_message:213 - "POST /api/dialer/call/initiate/ HTTP/1.1" 500 590
[2025-06-21 18:33:13,864] INFO django.utils.autoreload trigger_reload:265 - C:\Users\fazi\Desktop\machine task\secure-dashboard\backend\dialer\services.py changed, reloading.
[2025-06-21 18:33:15,056] INFO django.utils.autoreload run_with_reloader:667 - Watching for file changes with StatReloader
[2025-06-21 18:35:02,407] ERROR django.security.DisallowedHost log_response:253 - Invalid HTTP_HOST header: 'ddfa-103-70-197-46.ngrok-free.app'. You may need to add 'ddfa-103-70-197-46.ngrok-free.app' to ALLOWED_HOSTS.
Traceback (most recent call last):
  File "C:\Users\fazi\Desktop\machine task\secure-dashboard\backend\venv\Lib\site-packages\django\core\handlers\exception.py", line 55, in inner
    response = get_response(request)
               ^^^^^^^^^^^^^^^^^^^^^
  File "C:\Users\fazi\Desktop\machine task\secure-dashboard\backend\venv\Lib\site-packages\django\utils\deprecation.py", line 119, in __call__
    response = self.process_request(request)
               ^^^^^^^^^^^^^^^^^^^^^^^^^^^^^
  File "C:\Users\fazi\Desktop\machine task\secure-dashboard\backend\venv\Lib\site-packages\django\middleware\common.py", line 48, in process_request
    host = request.get_host()
           ^^^^^^^^^^^^^^^^^^
  File "C:\Users\fazi\Desktop\machine task\secure-dashboard\backend\venv\Lib\site-packages\django\http\request.py", line 191, in get_host
    raise DisallowedHost(msg)
django.core.exceptions.DisallowedHost: Invalid HTTP_HOST header: 'ddfa-103-70-197-46.ngrok-free.app'. You may need to add 'ddfa-103-70-197-46.ngrok-free.app' to ALLOWED_HOSTS.
[2025-06-21 18:35:02,411] WARNING django.server log_message:213 - "GET / HTTP/1.1" 400 82107
[2025-06-21 18:35:02,804] ERROR django.security.DisallowedHost log_response:253 - Invalid HTTP_HOST header: 'ddfa-103-70-197-46.ngrok-free.app'. You may need to add 'ddfa-103-70-197-46.ngrok-free.app' to ALLOWED_HOSTS.
Traceback (most recent call last):
  File "C:\Users\fazi\Desktop\machine task\secure-dashboard\backend\venv\Lib\site-packages\django\core\handlers\exception.py", line 55, in inner
    response = get_response(request)
               ^^^^^^^^^^^^^^^^^^^^^
  File "C:\Users\fazi\Desktop\machine task\secure-dashboard\backend\venv\Lib\site-packages\django\utils\deprecation.py", line 119, in __call__
    response = self.process_request(request)
               ^^^^^^^^^^^^^^^^^^^^^^^^^^^^^
  File "C:\Users\fazi\Desktop\machine task\secure-dashboard\backend\venv\Lib\site-packages\django\middleware\common.py", line 48, in process_request
    host = request.get_host()
           ^^^^^^^^^^^^^^^^^^
  File "C:\Users\fazi\Desktop\machine task\secure-dashboard\backend\venv\Lib\site-packages\django\http\request.py", line 191, in get_host
    raise DisallowedHost(msg)
django.core.exceptions.DisallowedHost: Invalid HTTP_HOST header: 'ddfa-103-70-197-46.ngrok-free.app'. You may need to add 'ddfa-103-70-197-46.ngrok-free.app' to ALLOWED_HOSTS.
[2025-06-21 18:35:02,808] WARNING django.server log_message:213 - "GET /favicon.ico HTTP/1.1" 400 81947
[2025-06-21 18:35:39,967] INFO django.utils.autoreload trigger_reload:265 - C:\Users\fazi\Desktop\machine task\secure-dashboard\backend\secure_dashboard\settings.py changed, reloading.
[2025-06-21 18:35:41,452] INFO django.utils.autoreload run_with_reloader:667 - Watching for file changes with StatReloader
[2025-06-21 18:35:46,235] INFO django.utils.autoreload trigger_reload:265 - C:\Users\fazi\Desktop\machine task\secure-dashboard\backend\secure_dashboard\settings.py changed, reloading.
[2025-06-21 18:35:47,514] INFO django.utils.autoreload run_with_reloader:667 - Watching for file changes with StatReloader
[2025-06-21 18:35:50,719] INFO django.utils.autoreload trigger_reload:265 - C:\Users\fazi\Desktop\machine task\secure-dashboard\backend\secure_dashboard\settings.py changed, reloading.
[2025-06-21 18:35:51,877] INFO django.utils.autoreload run_with_reloader:667 - Watching for file changes with StatReloader
[2025-06-21 18:36:25,423] INFO django.utils.autoreload trigger_reload:265 - C:\Users\fazi\Desktop\machine task\secure-dashboard\backend\secure_dashboard\settings.py changed, reloading.
[2025-06-21 18:36:26,665] INFO django.utils.autoreload run_with_reloader:667 - Watching for file changes with StatReloader
[2025-06-21 18:37:37,293] INFO django.utils.autoreload trigger_reload:265 - C:\Users\fazi\Desktop\machine task\secure-dashboard\backend\secure_dashboard\settings.py changed, reloading.
[2025-06-21 18:37:38,667] INFO django.utils.autoreload run_with_reloader:667 - Watching for file changes with StatReloader
[2025-06-21 18:37:41,896] INFO django.utils.autoreload trigger_reload:265 - C:\Users\fazi\Desktop\machine task\secure-dashboard\backend\secure_dashboard\settings.py changed, reloading.
[2025-06-21 18:37:43,804] INFO django.utils.autoreload run_with_reloader:667 - Watching for file changes with StatReloader
[2025-06-21 18:37:45,731] ERROR django.security.DisallowedHost log_response:253 - Invalid HTTP_HOST header: 'ddfa-103-70-197-46.ngrok-free.app'. You may need to add 'ddfa-103-70-197-46.ngrok-free.app' to ALLOWED_HOSTS.
Traceback (most recent call last):
  File "C:\Users\fazi\Desktop\machine task\secure-dashboard\backend\venv\Lib\site-packages\django\core\handlers\exception.py", line 55, in inner
    response = get_response(request)
               ^^^^^^^^^^^^^^^^^^^^^
  File "C:\Users\fazi\Desktop\machine task\secure-dashboard\backend\venv\Lib\site-packages\django\utils\deprecation.py", line 119, in __call__
    response = self.process_request(request)
               ^^^^^^^^^^^^^^^^^^^^^^^^^^^^^
  File "C:\Users\fazi\Desktop\machine task\secure-dashboard\backend\venv\Lib\site-packages\django\middleware\common.py", line 48, in process_request
    host = request.get_host()
           ^^^^^^^^^^^^^^^^^^
  File "C:\Users\fazi\Desktop\machine task\secure-dashboard\backend\venv\Lib\site-packages\django\http\request.py", line 191, in get_host
    raise DisallowedHost(msg)
django.core.exceptions.DisallowedHost: Invalid HTTP_HOST header: 'ddfa-103-70-197-46.ngrok-free.app'. You may need to add 'ddfa-103-70-197-46.ngrok-free.app' to ALLOWED_HOSTS.
[2025-06-21 18:37:45,737] WARNING django.server log_message:213 - "GET / HTTP/1.1" 400 82203
[2025-06-21 18:37:46,046] ERROR django.security.DisallowedHost log_response:253 - Invalid HTTP_HOST header: 'ddfa-103-70-197-46.ngrok-free.app'. You may need to add 'ddfa-103-70-197-46.ngrok-free.app' to ALLOWED_HOSTS.
Traceback (most recent call last):
  File "C:\Users\fazi\Desktop\machine task\secure-dashboard\backend\venv\Lib\site-packages\django\core\handlers\exception.py", line 55, in inner
    response = get_response(request)
               ^^^^^^^^^^^^^^^^^^^^^
  File "C:\Users\fazi\Desktop\machine task\secure-dashboard\backend\venv\Lib\site-packages\django\utils\deprecation.py", line 119, in __call__
    response = self.process_request(request)
               ^^^^^^^^^^^^^^^^^^^^^^^^^^^^^
  File "C:\Users\fazi\Desktop\machine task\secure-dashboard\backend\venv\Lib\site-packages\django\middleware\common.py", line 48, in process_request
    host = request.get_host()
           ^^^^^^^^^^^^^^^^^^
  File "C:\Users\fazi\Desktop\machine task\secure-dashboard\backend\venv\Lib\site-packages\django\http\request.py", line 191, in get_host
    raise DisallowedHost(msg)
django.core.exceptions.DisallowedHost: Invalid HTTP_HOST header: 'ddfa-103-70-197-46.ngrok-free.app'. You may need to add 'ddfa-103-70-197-46.ngrok-free.app' to ALLOWED_HOSTS.
[2025-06-21 18:37:46,050] WARNING django.server log_message:213 - "GET /favicon.ico HTTP/1.1" 400 82043
[2025-06-21 18:38:34,227] INFO django.utils.autoreload trigger_reload:265 - C:\Users\fazi\Desktop\machine task\secure-dashboard\backend\secure_dashboard\settings.py changed, reloading.
[2025-06-21 18:38:35,456] INFO django.utils.autoreload run_with_reloader:667 - Watching for file changes with StatReloader
[2025-06-21 18:38:42,420] INFO django.utils.autoreload trigger_reload:265 - C:\Users\fazi\Desktop\machine task\secure-dashboard\backend\secure_dashboard\settings.py changed, reloading.
[2025-06-21 18:38:43,798] INFO django.utils.autoreload run_with_reloader:667 - Watching for file changes with StatReloader
[2025-06-21 18:39:24,092] INFO django.utils.autoreload trigger_reload:265 - C:\Users\fazi\Desktop\machine task\secure-dashboard\backend\secure_dashboard\settings.py changed, reloading.
[2025-06-21 18:39:25,685] INFO django.utils.autoreload run_with_reloader:667 - Watching for file changes with StatReloader
[2025-06-22 00:41:46,805] INFO django.utils.autoreload run_with_reloader:667 - Watching for file changes with StatReloader
[2025-06-22 00:44:43,490] INFO django.utils.autoreload trigger_reload:265 - C:\Users\fazi\Desktop\machine task\secure-dashboard\backend\secure_dashboard\settings.py changed, reloading.
[2025-06-22 00:44:44,804] INFO django.utils.autoreload run_with_reloader:667 - Watching for file changes with StatReloader
[2025-06-22 00:44:47,566] INFO django.utils.autoreload trigger_reload:265 - C:\Users\fazi\Desktop\machine task\secure-dashboard\backend\secure_dashboard\settings.py changed, reloading.
[2025-06-22 00:44:48,521] INFO django.utils.autoreload run_with_reloader:667 - Watching for file changes with StatReloader
[2025-06-22 00:44:58,386] INFO django.utils.autoreload trigger_reload:265 - C:\Users\fazi\Desktop\machine task\secure-dashboard\backend\secure_dashboard\settings.py changed, reloading.
[2025-06-22 00:44:59,534] INFO django.utils.autoreload run_with_reloader:667 - Watching for file changes with StatReloader
[2025-06-22 00:45:06,719] WARNING django.request log_response:253 - Not Found: /
[2025-06-22 00:45:06,721] WARNING django.server log_message:213 - "GET / HTTP/1.1" 404 2639
[2025-06-22 00:45:06,894] WARNING django.request log_response:253 - Not Found: /favicon.ico
[2025-06-22 00:45:06,895] WARNING django.server log_message:213 - "GET /favicon.ico HTTP/1.1" 404 2690
[2025-06-22 00:55:07,656] INFO django.server log_message:213 - "OPTIONS /api/auth/profile/ HTTP/1.1" 200 0
[2025-06-22 00:55:07,677] INFO django.server log_message:213 - "OPTIONS /api/auth/profile/ HTTP/1.1" 200 0
[2025-06-22 00:55:43,906] INFO django.server log_message:213 - "OPTIONS /api/auth/webauthn/authenticate/begin/ HTTP/1.1" 200 0
[2025-06-22 00:55:44,013] INFO django.server log_message:213 - "POST /api/auth/webauthn/authenticate/begin/ HTTP/1.1" 200 327
[2025-06-22 00:57:30,822] INFO django.server log_message:213 - "OPTIONS /api/auth/webauthn/authenticate/complete/ HTTP/1.1" 200 0
[2025-06-22 00:57:31,070] INFO django.server log_message:213 - "POST /api/auth/webauthn/authenticate/complete/ HTTP/1.1" 200 678
[2025-06-22 01:01:01,587] INFO django.utils.autoreload trigger_reload:265 - C:\Users\fazi\Desktop\machine task\secure-dashboard\backend\secure_dashboard\settings.py changed, reloading.
[2025-06-22 01:01:02,946] INFO django.utils.autoreload run_with_reloader:667 - Watching for file changes with StatReloader
[2025-06-22 01:01:06,046] INFO django.utils.autoreload trigger_reload:265 - C:\Users\fazi\Desktop\machine task\secure-dashboard\backend\secure_dashboard\settings.py changed, reloading.
[2025-06-22 01:01:07,349] INFO django.utils.autoreload run_with_reloader:667 - Watching for file changes with StatReloader
[2025-06-22 01:01:10,070] INFO django.utils.autoreload trigger_reload:265 - C:\Users\fazi\Desktop\machine task\secure-dashboard\backend\secure_dashboard\settings.py changed, reloading.
[2025-06-22 01:01:11,205] INFO django.utils.autoreload run_with_reloader:667 - Watching for file changes with StatReloader
[2025-06-22 01:01:13,990] INFO django.utils.autoreload trigger_reload:265 - C:\Users\fazi\Desktop\machine task\secure-dashboard\backend\secure_dashboard\settings.py changed, reloading.
[2025-06-22 01:01:15,027] INFO django.utils.autoreload run_with_reloader:667 - Watching for file changes with StatReloader
[2025-06-22 01:01:21,944] WARNING django.request log_response:253 - Not Found: /
[2025-06-22 01:01:21,945] WARNING django.server log_message:213 - "GET / HTTP/1.1" 404 2639
[2025-06-22 01:03:00,841] INFO django.server log_message:213 - "OPTIONS /api/auth/webauthn/authenticate/begin/ HTTP/1.1" 200 0
[2025-06-22 01:03:00,938] INFO django.server log_message:213 - "POST /api/auth/webauthn/authenticate/begin/ HTTP/1.1" 200 327
[2025-06-22 01:03:32,137] INFO django.server log_message:213 - "OPTIONS /api/auth/webauthn/authenticate/complete/ HTTP/1.1" 200 0
[2025-06-22 01:03:32,399] INFO django.server log_message:213 - "POST /api/auth/webauthn/authenticate/complete/ HTTP/1.1" 200 678
[2025-06-22 01:03:32,529] INFO django.server log_message:213 - "OPTIONS /api/auth/profile/ HTTP/1.1" 200 0
[2025-06-22 01:03:32,531] INFO django.server log_message:213 - "OPTIONS /api/auth/profile/ HTTP/1.1" 200 0
[2025-06-22 01:04:46,405] INFO django.server log_message:213 - "OPTIONS /api/auth/profile/ HTTP/1.1" 200 0
[2025-06-22 01:04:46,407] INFO django.server log_message:213 - "OPTIONS /api/auth/profile/ HTTP/1.1" 200 0
[2025-06-22 01:04:46,479] INFO django.server log_message:213 - "OPTIONS /api/auth/profile/ HTTP/1.1" 200 0
[2025-06-22 01:04:46,481] INFO django.server log_message:213 - "OPTIONS /api/auth/profile/ HTTP/1.1" 200 0
[2025-06-22 01:05:15,452] INFO django.utils.autoreload trigger_reload:265 - C:\Users\fazi\Desktop\machine task\secure-dashboard\backend\secure_dashboard\settings.py changed, reloading.
[2025-06-22 01:05:16,772] INFO django.utils.autoreload run_with_reloader:667 - Watching for file changes with StatReloader
[2025-06-22 01:05:58,836] INFO django.utils.autoreload trigger_reload:265 - C:\Users\fazi\Desktop\machine task\secure-dashboard\backend\secure_dashboard\settings.py changed, reloading.
[2025-06-22 01:05:59,960] INFO django.utils.autoreload run_with_reloader:667 - Watching for file changes with StatReloader
[2025-06-22 01:06:07,382] INFO django.utils.autoreload trigger_reload:265 - C:\Users\fazi\Desktop\machine task\secure-dashboard\backend\secure_dashboard\settings.py changed, reloading.
[2025-06-22 01:06:08,651] INFO django.utils.autoreload run_with_reloader:667 - Watching for file changes with StatReloader
[2025-06-22 01:06:11,413] INFO django.utils.autoreload trigger_reload:265 - C:\Users\fazi\Desktop\machine task\secure-dashboard\backend\secure_dashboard\settings.py changed, reloading.
[2025-06-22 01:06:12,333] INFO django.utils.autoreload run_with_reloader:667 - Watching for file changes with StatReloader
[2025-06-22 01:06:14,922] INFO django.utils.autoreload trigger_reload:265 - C:\Users\fazi\Desktop\machine task\secure-dashboard\backend\secure_dashboard\settings.py changed, reloading.
[2025-06-22 01:06:15,978] INFO django.utils.autoreload run_with_reloader:667 - Watching for file changes with StatReloader
[2025-06-22 01:06:39,880] INFO django.utils.autoreload trigger_reload:265 - C:\Users\fazi\Desktop\machine task\secure-dashboard\backend\secure_dashboard\settings.py changed, reloading.
[2025-06-22 01:06:40,958] INFO django.utils.autoreload run_with_reloader:667 - Watching for file changes with StatReloader
[2025-06-22 01:06:52,593] INFO django.utils.autoreload run_with_reloader:667 - Watching for file changes with StatReloader
[2025-06-22 01:07:17,489] INFO django.utils.autoreload trigger_reload:265 - C:\Users\fazi\Desktop\machine task\secure-dashboard\backend\secure_dashboard\settings.py changed, reloading.
[2025-06-22 01:07:30,736] INFO django.utils.autoreload run_with_reloader:667 - Watching for file changes with StatReloader
[2025-06-22 01:07:46,704] INFO django.utils.autoreload trigger_reload:265 - C:\Users\fazi\Desktop\machine task\secure-dashboard\backend\secure_dashboard\settings.py changed, reloading.
[2025-06-22 01:07:47,734] INFO django.utils.autoreload run_with_reloader:667 - Watching for file changes with StatReloader
[2025-06-22 01:08:00,146] INFO django.utils.autoreload trigger_reload:265 - C:\Users\fazi\Desktop\machine task\secure-dashboard\backend\secure_dashboard\settings.py changed, reloading.
[2025-06-22 01:08:01,126] INFO django.utils.autoreload run_with_reloader:667 - Watching for file changes with StatReloader
[2025-06-22 01:09:12,772] INFO django.utils.autoreload trigger_reload:265 - C:\Users\fazi\Desktop\machine task\secure-dashboard\backend\secure_dashboard\settings.py changed, reloading.
[2025-06-22 01:09:14,071] INFO django.utils.autoreload run_with_reloader:667 - Watching for file changes with StatReloader
[2025-06-22 01:13:57,850] INFO django.utils.autoreload trigger_reload:265 - C:\Users\fazi\Desktop\machine task\secure-dashboard\backend\secure_dashboard\settings.py changed, reloading.
[2025-06-22 01:13:59,029] INFO django.utils.autoreload run_with_reloader:667 - Watching for file changes with StatReloader
[2025-06-22 01:25:58,153] INFO django.utils.autoreload trigger_reload:265 - C:\Users\fazi\Desktop\machine task\secure-dashboard\backend\secure_dashboard\settings.py changed, reloading.
[2025-06-22 01:25:59,091] INFO django.utils.autoreload run_with_reloader:667 - Watching for file changes with StatReloader
[2025-06-22 01:30:32,089] WARNING django.request log_response:253 - Unauthorized: /api/auth/profile/
[2025-06-22 01:30:32,089] WARNING django.server log_message:213 - "GET /api/auth/profile/ HTTP/1.1" 401 5189
[2025-06-22 01:30:32,468] INFO django.server log_message:213 - "GET /static/rest_framework/css/bootstrap.min.css HTTP/1.1" 200 121457
[2025-06-22 01:30:32,529] INFO django.server log_message:213 - "GET /static/rest_framework/js/jquery-3.7.1.min.js HTTP/1.1" 200 87533
[2025-06-22 01:30:32,559] INFO django.server log_message:213 - "GET /static/rest_framework/css/prettify.css HTTP/1.1" 200 817
[2025-06-22 01:30:32,596] INFO django.server log_message:213 - "GET /static/rest_framework/css/bootstrap-tweaks.css HTTP/1.1" 200 3426
[2025-06-22 01:30:32,637] INFO django.server log_message:213 - "GET /static/rest_framework/js/bootstrap.min.js HTTP/1.1" 200 39680
[2025-06-22 01:30:32,654] INFO django.server log_message:213 - "GET /static/rest_framework/js/load-ajax-form.js HTTP/1.1" 200 59
[2025-06-22 01:30:32,674] INFO django.server log_message:213 - "GET /static/rest_framework/css/default.css HTTP/1.1" 200 1152
[2025-06-22 01:30:32,677] INFO django.server log_message:213 - "GET /static/rest_framework/js/csrf.js HTTP/1.1" 200 1793
[2025-06-22 01:30:32,687] INFO django.server log_message:213 - "GET /static/rest_framework/js/default.js HTTP/1.1" 200 1268
[2025-06-22 01:30:32,688] INFO django.server log_message:213 - "GET /static/rest_framework/js/ajax-form.js HTTP/1.1" 200 3796
[2025-06-22 01:30:32,690] INFO django.server log_message:213 - "GET /static/rest_framework/js/prettify-min.js HTTP/1.1" 200 13632
[2025-06-22 01:30:32,753] INFO django.server log_message:213 - "GET /static/rest_framework/img/grid.png HTTP/1.1" 200 1458
[2025-06-22 01:30:32,833] WARNING django.request log_response:253 - Not Found: /favicon.ico
[2025-06-22 01:30:32,834] WARNING django.server log_message:213 - "GET /favicon.ico HTTP/1.1" 404 2690
